Workbook

Sheet GameTracker
A1: GameID | B1: Date | C1: URL | D1: Winner | E1: Game Duration | F1: Player Count | G1: Total Games | H1: =COUNTIF(A2:A100,">0") -> 87 | S1: Kills
A2: 1 | B2: 44967 | C2: https://www.youtube.com/watch?v=M6lJ_LsCLRc | D2: {=INDEX(GameStats!C:C, MATCH(1, (GameStats!A:A=A2)*(GameStats!D:D=1), 0))} -> SoXu | E2: {=INDEX(GameStats!E:E, MATCH(1, (GameStats!A:A=A2)*(GameStats!D:D=1), 0))} -> 111 | F2: =COUNTIF(GameStats!A:A,GameTracker!A2) -> 22 | G2: Tracked | H2: =COUNTIF(F2:F100,">0") -> 41
A3: 2 | B3: 44974 | C3: https://www.youtube.com/watch?v=zjNx9hXFvAk | D3: {=INDEX(GameStats!C:C, MATCH(1, (GameStats!A:A=A3)*(GameStats!D:D=1), 0))} -> SoXu | E3: {=INDEX(GameStats!E:E, MATCH(1, (GameStats!A:A=A3)*(GameStats!D:D=1), 0))} -> 111 | F3: =COUNTIF(GameStats!A:A,GameTracker!A3) -> 22 | H3: =H2/H1 -> 0.47126437
A4: 3 | B4: 44981 | C4: NONE | D4: {=INDEX(GameStats!C:C, MATCH(1, (GameStats!A:A=A4)*(GameStats!D:D=1), 0))} -> Dauda | E4: {=INDEX(GameStats!E:E, MATCH(1, (GameStats!A:A=A4)*(GameStats!D:D=1), 0))} -> 100 | F4: =COUNTIF(GameStats!A:A,GameTracker!A4) -> 1
A5: 4 | B5: 44988 | C5: https://www.youtube.com/watch?v=3v7FioL8DQQ | D5: {=INDEX(GameStats!C:C, MATCH(1, (GameStats!A:A=A5)*(GameStats!D:D=1), 0))} -> SoXu | E5: {=INDEX(GameStats!E:E, MATCH(1, (GameStats!A:A=A5)*(GameStats!D:D=1), 0))} -> 80 | F5: =COUNTIF(GameStats!A:A,GameTracker!A5) -> 23
A6: 5 | B6: 44995 | C6: https://www.youtube.com/watch?v=bu4V_Y9th6U | D6: {=INDEX(GameStats!C:C, MATCH(1, (GameStats!A:A=A6)*(GameStats!D:D=1), 0))} -> Easterbunny | E6: {=INDEX(GameStats!E:E, MATCH(1, (GameStats!A:A=A6)*(GameStats!D:D=1), 0))} -> 85 | F6: =COUNTIF(GameStats!A:A,GameTracker!A6) -> 21
A7: 6 | B7: 45002 | C7: https://www.youtube.com/watch?v=OKh4b3KYraA | D7: {=INDEX(GameStats!C:C, MATCH(1, (GameStats!A:A=A7)*(GameStats!D:D=1), 0))} -> cadiz32 | E7: {=INDEX(GameStats!E:E, MATCH(1, (GameStats!A:A=A7)*(GameStats!D:D=1), 0))} -> 125 | F7: =COUNTIF(GameStats!A:A,GameTracker!A7) -> 23
A8: 7 | B8: 45009 | C8: https://www.youtube.com/watch?v=N4AR3osAPFU | D8: {=INDEX(GameStats!C:C, MATCH(1, (GameStats!A:A=A8)*(GameStats!D:D=1), 0))} -> SoXu | E8: {=INDEX(GameStats!E:E, MATCH(1, (GameStats!A:A=A8)*(GameStats!D:D=1), 0))} -> 87 | F8: =COUNTIF(GameStats!A:A,GameTracker!A8) -> 22
A9: 8 | B9: 45016 | C9: https://www.youtube.com/watch?v=SFX4LIiGgQA | D9: {=INDEX(GameStats!C:C, MATCH(1, (GameStats!A:A=A9)*(GameStats!D:D=1), 0))} -> Jirenuber | E9: {=INDEX(GameStats!E:E, MATCH(1, (GameStats!A:A=A9)*(GameStats!D:D=1), 0))} -> 105 | F9: =COUNTIF(GameStats!A:A,GameTracker!A9) -> 22
A10: 9 | B10: 45023 | C10: https://www.youtube.com/watch?v=b91lKBytRoY | D10: {=INDEX(GameStats!C:C, MATCH(1, (GameStats!A:A=A10)*(GameStats!D:D=1), 0))} -> Dauda | E10: {=INDEX(GameStats!E:E, MATCH(1, (GameStats!A:A=A10)*(GameStats!D:D=1), 0))} -> 79 | F10: =COUNTIF(GameStats!A:A,GameTracker!A10) -> 23
A11: 10 | B11: 45030 | C11: https://www.youtube.com/watch?v=OfY8RDSnJ_Q | D11: {=INDEX(GameStats!C:C, MATCH(1, (GameStats!A:A=A11)*(GameStats!D:D=1), 0))} -> xFreshNeZz | E11: {=INDEX(GameStats!E:E, MATCH(1, (GameStats!A:A=A11)*(GameStats!D:D=1), 0))} -> 72 | F11: =COUNTIF(GameStats!A:A,GameTracker!A11) -> 22
A12: 11 | B12: 45037 | C12: https://www.youtube.com/watch?v=GFInSu-wSUs | D12: {=INDEX(GameStats!C:C, MATCH(1, (GameStats!A:A=A12)*(GameStats!D:D=1), 0))} -> Dauda | E12: {=INDEX(GameStats!E:E, MATCH(1, (GameStats!A:A=A12)*(GameStats!D:D=1), 0))} -> 35 | F12: =COUNTIF(GameStats!A:A,GameTracker!A12) -> 23
A13: 12 | B13: 45044 | C13: https://www.youtube.com/watch?v=lAA40p2T6cU | D13: {=INDEX(GameStats!C:C, MATCH(1, (GameStats!A:A=A13)*(GameStats!D:D=1), 0))} -> StarDrifter | E13: {=INDEX(GameStats!E:E, MATCH(1, (GameStats!A:A=A13)*(GameStats!D:D=1), 0))} -> 80 | F13: =COUNTIF(GameStats!A:A,GameTracker!A13) -> 23
A14: 13 | B14: 45051 | C14: https://www.youtube.com/watch?v=E8OcnbLDR3s | D14: {=INDEX(GameStats!C:C, MATCH(1, (GameStats!A:A=A14)*(GameStats!D:D=1), 0))} -> #N/A | E14: {=INDEX(GameStats!E:E, MATCH(1, (GameStats!A:A=A14)*(GameStats!D:D=1), 0))} -> #N/A | F14: =COUNTIF(GameStats!A:A,GameTracker!A14) -> 0
A15: 14 | B15: 45058 | C15: https://www.youtube.com/watch?v=8mZ45ZSDTAk | D15: {=INDEX(GameStats!C:C, MATCH(1, (GameStats!A:A=A15)*(GameStats!D:D=1), 0))} -> #N/A | E15: {=INDEX(GameStats!E:E, MATCH(1, (GameStats!A:A=A15)*(GameStats!D:D=1), 0))} -> #N/A | F15: =COUNTIF(GameStats!A:A,GameTracker!A15) -> 0
... A75: 74 | B75: 45478 | C75: https://youtube.com/live/rklxFyIYVao | D75: {=INDEX(GameStats!C:C, MATCH(1, (GameStats!A:A=A75)*(GameStats!D:D=1), 0))} -> MinaMoto | E75: {=INDEX(GameStats!E:E, MATCH(1, (GameStats!A:A=A75)*(GameStats!D:D=1), 0))} -> 85 | F75: =COUNTIF(GameStats!A:A,GameTracker!A75) -> 23
A76: 75 | B76: 45485 | C76: https://www.youtube.com/live/UtWByTodLA4 | D76: {=INDEX(GameStats!C:C, MATCH(1, (GameStats!A:A=A76)*(GameStats!D:D=1), 0))} -> #N/A | E76: {=INDEX(GameStats!E:E, MATCH(1, (GameStats!A:A=A76)*(GameStats!D:D=1), 0))} -> #N/A | F76: =COUNTIF(GameStats!A:A,GameTracker!A76) -> 0 | G76: TBD
A77: 76 | B77: 45492 | C77: https://youtube.com/live/aEmW6NAB8rg | D77: {=INDEX(GameStats!C:C, MATCH(1, (GameStats!A:A=A77)*(GameStats!D:D=1), 0))} -> idorobots | E77: {=INDEX(GameStats!E:E, MATCH(1, (GameStats!A:A=A77)*(GameStats!D:D=1), 0))} -> 75 | F77: =COUNTIF(GameStats!A:A,GameTracker!A77) -> 22
A78: 77 | B78: 45499 | C78: https://youtube.com/live/I6zwuL8wX-E | D78: {=INDEX(GameStats!C:C, MATCH(1, (GameStats!A:A=A78)*(GameStats!D:D=1), 0))} -> idorobots | E78: {=INDEX(GameStats!E:E, MATCH(1, (GameStats!A:A=A78)*(GameStats!D:D=1), 0))} -> 68 | F78: =COUNTIF(GameStats!A:A,GameTracker!A78) -> 22
A79: 78 | B79: 45506 | C79: https://www.youtube.com/live/-R1UF5px40s | D79: {=INDEX(GameStats!C:C, MATCH(1, (GameStats!A:A=A79)*(GameStats!D:D=1), 0))} -> Powerstroke1 | E79: {=INDEX(GameStats!E:E, MATCH(1, (GameStats!A:A=A79)*(GameStats!D:D=1), 0))} -> 173 | F79: =COUNTIF(GameStats!A:A,GameTracker!A79) -> 22
A80: 79 | B80: 45513 | C80: https://www.youtube.com/live/gXC7Rm__s6A | D80: {=INDEX(GameStats!C:C, MATCH(1, (GameStats!A:A=A80)*(GameStats!D:D=1), 0))} -> Soxu | E80: {=INDEX(GameStats!E:E, MATCH(1, (GameStats!A:A=A80)*(GameStats!D:D=1), 0))} -> 121 | F80: =COUNTIF(GameStats!A:A,GameTracker!A80) -> 22
A81: 80 | B81: 45520 | C81: https://www.youtube.com/live/nc_Pko99qjI | D81: {=INDEX(GameStats!C:C, MATCH(1, (GameStats!A:A=A81)*(GameStats!D:D=1), 0))} -> Smw | E81: {=INDEX(GameStats!E:E, MATCH(1, (GameStats!A:A=A81)*(GameStats!D:D=1), 0))} -> 205 | F81: =COUNTIF(GameStats!A:A,GameTracker!A81) -> 23
A82: 81 | B82: 45527 | C82: https://youtube.com/live/QQIONeqdW60 | D82: {=INDEX(GameStats!C:C, MATCH(1, (GameStats!A:A=A82)*(GameStats!D:D=1), 0))} -> SoXu | E82: {=INDEX(GameStats!E:E, MATCH(1, (GameStats!A:A=A82)*(GameStats!D:D=1), 0))} -> 134 | F82: =COUNTIF(GameStats!A:A,GameTracker!A82) -> 23
A83: 82 | B83: 45534 | C83: https://youtube.com/live/5hKBpMhwLS0 | D83: {=INDEX(GameStats!C:C, MATCH(1, (GameStats!A:A=A83)*(GameStats!D:D=1), 0))} -> easterbunny | E83: {=INDEX(GameStats!E:E, MATCH(1, (GameStats!A:A=A83)*(GameStats!D:D=1), 0))} -> 103 | F83: =COUNTIF(GameStats!A:A,GameTracker!A83) -> 23
A84: 83 | B84: 45541 | C84: https://youtube.com/live/X-XizsYuOs4 | D84: {=INDEX(GameStats!C:C, MATCH(1, (GameStats!A:A=A84)*(GameStats!D:D=1), 0))} -> SoXu | E84: {=INDEX(GameStats!E:E, MATCH(1, (GameStats!A:A=A84)*(GameStats!D:D=1), 0))} -> 120 | F84: =COUNTIF(GameStats!A:A,GameTracker!A84) -> 22
A85: 84 | B85: 45548 | C85: https://www.youtube.com/live/QX-nBH9AS3s | D85: {=INDEX(GameStats!C:C, MATCH(1, (GameStats!A:A=A85)*(GameStats!D:D=1), 0))} -> Faker | E85: {=INDEX(GameStats!E:E, MATCH(1, (GameStats!A:A=A85)*(GameStats!D:D=1), 0))} -> 171 | F85: =COUNTIF(GameStats!A:A,GameTracker!A85) -> 23
A86: 85 | B86: 45555 | C86: https://www.youtube.com/live/jcMzd2SwirE | D86: {=INDEX(GameStats!C:C, MATCH(1, (GameStats!A:A=A86)*(GameStats!D:D=1), 0))} -> MSCIWORLD | E86: {=INDEX(GameStats!E:E, MATCH(1, (GameStats!A:A=A86)*(GameStats!D:D=1), 0))} -> 120 | F86: =COUNTIF(GameStats!A:A,GameTracker!A86) -> 23
A87: 86 | B87: 45562 | C87: https://www.youtube.com/live/j-_x9ZgXsyk | D87: {=INDEX(GameStats!C:C, MATCH(1, (GameStats!A:A=A87)*(GameStats!D:D=1), 0))} -> MSCIWORLD | E87: {=INDEX(GameStats!E:E, MATCH(1, (GameStats!A:A=A87)*(GameStats!D:D=1), 0))} -> 89 | F87: =COUNTIF(GameStats!A:A,GameTracker!A87) -> 23
A88: 87 | B88: 45569 | C88: https://www.youtube.com/watch?v=WltERhchUyw | D88: {=INDEX(GameStats!C:C, MATCH(1, (GameStats!A:A=A88)*(GameStats!D:D=1), 0))} -> Neo | E88: {=INDEX(GameStats!E:E, MATCH(1, (GameStats!A:A=A88)*(GameStats!D:D=1), 0))} -> 167 | F88: =COUNTIF(GameStats!A:A,GameTracker!A88) -> 22

Sheet GameStats
A1: GameID | B1: GameDate | C1: Player | D1: Rank | E1: Last Turn | F1: Kills | G1: Deaths | H1: KD | I1: Biggest Rival | J1: Comments
A2: 1 | B2: 44967 | C2: SoXu | D2: 1 | E2: 111 | F2: 10125 | G2: 8241 | H2: =F2/G2 -> 1.228613
A3: 1 | B3: 44967 | C3: Osb | D3: 2 | E3: 111 | F3: 9605 | G3: 7375 | H3: =F3/G3 -> 1.3023729
A4: 1 | B4: 44967 | C4: SodaFromHell | D4: 3 | E4: 111 | F4: 9416 | G4: 10636 | H4: =F4/G4 -> 0.88529522
A5: 1 | B5: 44967 | C5: Nightmare91 | D5: 4 | E5: 107 | F5: 2046 | G5: 1743 | H5: =F5/G5 -> 1.1738382
A6: 1 | B6: 44967 | C6: xFreshNeZz | D6: 5 | E6: 79 | F6: 915 | G6: 953 | H6: =F6/G6 -> 0.96012592
A7: 1 | B7: 44967 | C7: ColdMist | D7: 6 | E7: 72 | F7: 2141 | G7: 2390 | H7: =F7/G7 -> 0.8958159
A8: 1 | B8: 44967 | C8: Skyrone | D8: 7 | E8: 68 | F8: 547 | G8: 685 | H8: =F8/G8 -> 0.79854015
A9: 1 | B9: 44967 | C9: Jax | D9: 8 | E9: 62 | F9: 1295 | G9: 1285 | H9: =F9/G9 -> 1.0077821
A10: 1 | B10: 44967 | C10: Nerla | D10: 9 | E10: 38 | F10: 299 | G10: 438 | H10: =F10/G10 -> 0.6826484
A11: 1 | B11: 44967 | C11: kektus | D11: 10 | E11: 23 | F11: 96 | G11: 140 | H11: =F11/G11 -> 0.68571429
A12: 1 | B12: 44967 | C12: Trusty | D12: 11 | E12: 19 | F12: 118 | G12: 235 | H12: =F12/G12 -> 0.50212766
A13: 1 | B13: 44967 | C13: TwoFourThree | D13: 12 | E13: 14 | F13: 31 | G13: 139 | H13: =F13/G13 -> 0.22302158
... A149: 8 | B149: 45016 | C149: Quetra | D149: 14 | E149: 17 | F149: 277 | G149: 321 | H149: =F149/G149 -> 0.86292835
A150: 8 | B150: 45016 | C150: SoXu | D150: 15 | E150: 14 | F150: 166 | G150: 71 | H150: =F150/G150 -> 2.3380282 | J150: Disconnected
A151: 8 | B151: 45016 | C151: Universe | D151: 16 | E151: 12 | F151: 110 | G151: 138 | H151: =F151/G151 -> 0.79710145
A152: 8 | B152: 45016 | C152: Tempus | D152: 17 | E152: 10 | F152: 29 | G152: 100 | H152: =F152/G152 -> 0.29
A153: 8 | B153: 45016 | C153: Dirican | D153: 18 | E153: 9 | F153: 63 | G153: 76 | H153: =F153/G153 -> 0.82894737
A154: 8 | B154: 45016 | C154: tbatch1 | D154: 19 | E154: 8 | F154: 39 | G154: 80 | H154: =F154/G154 -> 0.4875
A155: 8 | B155: 45016 | C155: sordak | D155: 20 | E155: 4 | F155: 29 | G155: 37 | H155: =F155/G155 -> 0.78378378
A156: 8 | B156: 45016 | C156: Aventurier | D156: 21 | E156: 4 | F156: 11 | G156: 22 | H156: =F156/G156 -> 0.5
A157: 8 | B157: 45016 | C157: Obli | D157: 22 | E157: 2 | F157: 4 | G157: 8 | H157: =F157/G157 -> 0.5
A158: 9 | B158: 45023 | C158: Dauda | D158: 1 | E158: 79 | F158: 5064 | G158: 3799 | H158: =F158/G158 -> 1.3329824
A159: 9 | B159: 45023 | C159: Certitude | D159: 2 | E159: 79 | F159: 1279 | G159: 683 | H159: =F159/G159 -> 1.8726208
A160: 9 | B160: 45023 | C160: MinaMoto | D160: 3 | E160: 79 | F160: 1802 | G160: 2039 | H160: =F160/G160 -> 0.88376655
A161: 9 | B161: 45023 | C161: Skyrone | D161: 4 | E161: 79 | F161: 674 | G161: 455 | H161: =F161/G161 -> 1.4813187
A162: 9 | B162: 45023 | C162: xFreshNeZz | D162: 5 | E162: 79 | F162: 787 | G162: 720 | H162: =F162/G162 -> 1.0930556
... A248: 12 | B248: 45044 | C248: noswear | D248: 23 | E248: 2 | F248: 0 | G248: 7 | H248: =F248/G248 -> 0
A249: 58 | B249: 45366 | C249: none | D249: 1 | E249: 178 | F249: 15449 | G249: 13621 | H249: =F249/G249 -> 1.1342045 | I249: tdawg
A250: 58 | B250: 45366 | C250: tdawg | D250: 2 | E250: 178 | F250: 21768 | G250: 16013 | H250: =F250/G250 -> 1.3593955 | I250: msciworld
A251: 58 | B251: 45366 | C251: msciworld | D251: 3 | E251: 178 | F251: 20778 | G251: 20267 | H251: =F251/G251 -> 1.0252134 | I251: tdawg
A252: 58 | B252: 45366 | C252: nicolai95 | D252: 4 | E252: 129 | F252: 4364 | G252: 5396 | H252: =F252/G252 -> 0.80874722 | I252: msciworld
A253: 58 | B253: 45366 | C253: derreger420 | D253: 5 | E253: 108 | F253: 3307 | G253: 5231 | H253: =F253/G253 -> 0.6321927 | I253: msciworld
A254: 58 | B254: 45366 | C254: mono | D254: 6 | E254: 83 | F254: 552 | G254: 1036 | H254: =F254/G254 -> 0.53281853 | I254: leviackerman
A255: 58 | B255: 45366 | C255: einz | D255: 7 | E255: 69 | F255: 1029 | G255: 2096 | H255: =F255/G255 -> 0.49093511 | I255: msciworld
A256: 58 | B256: 45366 | C256: finicky | D256: 8 | E256: 69 | F256: 1088 | G256: 542 | H256: =F256/G256 -> 2.0073801 | I256: nicolai95
A257: 58 | B257: 45366 | C257: smoko21 | D257: 9 | E257: 65 | F257: 933 | G257: 1374 | H257: =F257/G257 -> 0.6790393 | I257: nicolai95
A258: 58 | B258: 45366 | C258: leviackerman | D258: 10 | E258: 54 | F258: 1061 | G258: 1537 | H258: =F258/G258 -> 0.69030579 | I258: finicky
A259: 58 | B259: 45366 | C259: noctis | D259: 11 | E259: 51 | F259: 732 | G259: 1346 | H259: =F259/G259 -> 0.54383358 | I259: msciworld
A260: 58 | B260: 45366 | C260: hasooon | D260: 12 | E260: 36 | F260: 509 | G260: 494 | H260: =F260/G260 -> 1.0303644 | I260: noctis
...

Sheet All Players
A1: {=_xlfn.UNIQUE(GameStats!C:C)} -> Player
A2: SoXu
A3: Osb
A4: SodaFromHell
A5: Nightmare91
A6: xFreshNeZz
A7: ColdMist
A8: Skyrone
A9: Jax
A10: Nerla
A11: kektus
A12: Trusty
A13: TwoFourThree
... A293: Draeme
A294: 0

Sheet PlayerStats
A1: ='All Players'!A1 -> Player | B1: Wins | C1: Games Played | D1: Win Rate | E1: AVG Placement | F1: KD | G1: Total Rival Count | H1: Total Kills | I1: Total Deaths | J1: AVG Kills | K1: AVG Deaths | L1: AVG Rival Count | M1: ELO | N1: First Played | O1: Last Played | P1: Active | Q1: 43993
A2: ='All Players'!A2 -> SoXu | B2: =COUNTIFS(GameStats!C:C,A2,GameStats!D:D,"1",GameStats!B:B,">="&$Q$1) -> 9 | C2: =COUNTIFS(GameStats!C:C,A2,GameStats!B:B,">="&$Q$1) -> 26 | D2: =B2/C2 -> 0.34615385 | E2: =SUMIFS(GameStats!D:D,GameStats!C:C,A2,GameStats!B:B,">="&$Q$1)/C2 -> 5.7692308 | F2: =H2/I2 -> 1.1837031 | G2: =COUNTIFS(GameStats!I:I,A2,GameStats!B:B,">="&$Q$1) -> 47 | H2: =SUMIFS(GameStats!F:F,GameStats!C:C,A2,GameStats!B:B,">="&$Q$1) -> 175091 | I2: =SUMIFS(GameStats!G:G,GameStats!C:C,A2,GameStats!B:B,">="&$Q$1) -> 147918 | J2: =H2/C2 -> 6734.2692 | K2: =I2/C2 -> 5689.1538 | L2: =G2/C2 -> 1.8076923 | M2: =('Elo model'!$E$14*PlayerStats!D2) + ('Elo model'!$F$14*(1/PlayerStats!E2)) + ('Elo model'!$G$14*PlayerStats!F2) + ('Elo model'!$H$14*(PlayerStats!L2/4)) -> 0.43915803 | N2: =_xlfn.MINIFS(GameStats!B:B,GameStats!C:C,A2) -> 44967 | O2: =_xlfn.MAXIFS(GameStats!B:B,GameStats!C:C,A2) -> 45569 | P2: =IF(O2>$Q$1,TRUE) -> TRUE
A3: ='All Players'!A128 -> harakiri | B3: =COUNTIFS(GameStats!C:C,A3,GameStats!D:D,"1",GameStats!B:B,">="&$Q$1) -> 0 | C3: =COUNTIFS(GameStats!C:C,A3,GameStats!B:B,">="&$Q$1) -> 25 | D3: =B3/C3 -> 0 | E3: =SUMIFS(GameStats!D:D,GameStats!C:C,A3,GameStats!B:B,">="&$Q$1)/C3 -> 12.2 | F3: =H3/I3 -> 1.0107275 | G3: =COUNTIFS(GameStats!I:I,A3,GameStats!B:B,">="&$Q$1) -> 15 | H3: =SUMIFS(GameStats!F:F,GameStats!C:C,A3,GameStats!B:B,">="&$Q$1) -> 32317 | I3: =SUMIFS(GameStats!G:G,GameStats!C:C,A3,GameStats!B:B,">="&$Q$1) -> 31974 | J3: =H3/C3 -> 1292.68 | K3: =I3/C3 -> 1278.96 | L3: =G3/C3 -> 0.6 | M3: =('Elo model'!$E$14*PlayerStats!D128) + ('Elo model'!$F$14*(1/PlayerStats!E128)) + ('Elo model'!$G$14*(PlayerStats!F128/1.75)) + ('Elo model'!$H$14*(PlayerStats!L128/4)) -> 0.15221543 | N3: =_xlfn.MINIFS(GameStats!B:B,GameStats!C:C,A3) -> 45366 | O3: =_xlfn.MAXIFS(GameStats!B:B,GameStats!C:C,A3) -> 45562 | P3: =IF(O3>$Q$1,TRUE) -> TRUE
A4: ='All Players'!A6 -> xFreshNeZz | B4: =COUNTIFS(GameStats!C:C,A4,GameStats!D:D,"1",GameStats!B:B,">="&$Q$1) -> 1 | C4: =COUNTIFS(GameStats!C:C,A4,GameStats!B:B,">="&$Q$1) -> 23 | D4: =B4/C4 -> 0.043478261 | E4: =SUMIFS(GameStats!D:D,GameStats!C:C,A4,GameStats!B:B,">="&$Q$1)/C4 -> 8.2173913 | F4: =H4/I4 -> 1.0788082 | G4: =COUNTIFS(GameStats!I:I,A4,GameStats!B:B,">="&$Q$1) -> 16 | H4: =SUMIFS(GameStats!F:F,GameStats!C:C,A4,GameStats!B:B,">="&$Q$1) -> 47720 | I4: =SUMIFS(GameStats!G:G,GameStats!C:C,A4,GameStats!B:B,">="&$Q$1) -> 44234 | J4: =H4/C4 -> 2074.7826 | K4: =I4/C4 -> 1923.2174 | L4: =G4/C4 -> 0.69565217 | M4: =('Elo model'!$E$14*PlayerStats!D6) + ('Elo model'!$F$14*(1/PlayerStats!E6)) + ('Elo model'!$G$14*(PlayerStats!F6/1.75)) + ('Elo model'!$H$14*(PlayerStats!L6/4)) -> 0.13720123 | N4: =_xlfn.MINIFS(GameStats!B:B,GameStats!C:C,A4) -> 44967 | O4: =_xlfn.MAXIFS(GameStats!B:B,GameStats!C:C,A4) -> 45569 | P4: =IF(O4>$Q$1,TRUE) -> TRUE
A5: ='All Players'!A123 -> msciworld | B5: =COUNTIFS(GameStats!C:C,A5,GameStats!D:D,"1",GameStats!B:B,">="&$Q$1) -> 5 | C5: =COUNTIFS(GameStats!C:C,A5,GameStats!B:B,">="&$Q$1) -> 22 | D5: =B5/C5 -> 0.22727273 | E5: =SUMIFS(GameStats!D:D,GameStats!C:C,A5,GameStats!B:B,">="&$Q$1)/C5 -> 2.7727273 | F5: =H5/I5 -> 1.0774339 | G5: =COUNTIFS(GameStats!I:I,A5,GameStats!B:B,">="&$Q$1) -> 86 | H5: =SUMIFS(GameStats!F:F,GameStats!C:C,A5,GameStats!B:B,">="&$Q$1) -> 263174 | I5: =SUMIFS(GameStats!G:G,GameStats!C:C,A5,GameStats!B:B,">="&$Q$1) -> 244260 | J5: =H5/C5 -> 11962.455 | K5: =I5/C5 -> 11102.727 | L5: =G5/C5 -> 3.9090909 | M5: =('Elo model'!$E$14*PlayerStats!D123) + ('Elo model'!$F$14*(1/PlayerStats!E123)) + ('Elo model'!$G$14*(PlayerStats!F123/1.75)) + ('Elo model'!$H$14*(PlayerStats!L123/4)) -> 0.19207261 | N5: =_xlfn.MINIFS(GameStats!B:B,GameStats!C:C,A5) -> 45366 | O5: =_xlfn.MAXIFS(GameStats!B:B,GameStats!C:C,A5) -> 45569 | P5: =IF(O5>$Q$1,TRUE) -> TRUE
A6: ='All Players'!A22 -> Powerstroke1 | B6: =COUNTIFS(GameStats!C:C,A6,GameStats!D:D,"1",GameStats!B:B,">="&$Q$1) -> 1 | C6: =COUNTIFS(GameStats!C:C,A6,GameStats!B:B,">="&$Q$1) -> 20 | D6: =B6/C6 -> 0.05 | E6: =SUMIFS(GameStats!D:D,GameStats!C:C,A6,GameStats!B:B,">="&$Q$1)/C6 -> 13.55 | F6: =H6/I6 -> 0.90417887 | G6: =COUNTIFS(GameStats!I:I,A6,GameStats!B:B,">="&$Q$1) -> 13 | H6: =SUMIFS(GameStats!F:F,GameStats!C:C,A6,GameStats!B:B,">="&$Q$1) -> 29318 | I6: =SUMIFS(GameStats!G:G,GameStats!C:C,A6,GameStats!B:B,">="&$Q$1) -> 32425 | J6: =H6/C6 -> 1465.9 | K6: =I6/C6 -> 1621.25 | L6: =G6/C6 -> 0.65 | M6: =('Elo model'!$E$14*PlayerStats!D22) + ('Elo model'!$F$14*(1/PlayerStats!E22)) + ('Elo model'!$G$14*PlayerStats!F22) + ('Elo model'!$H$14*(PlayerStats!L22/4)) -> 0.31536874 | N6: =_xlfn.MINIFS(GameStats!B:B,GameStats!C:C,A6) -> 44967 | O6: =_xlfn.MAXIFS(GameStats!B:B,GameStats!C:C,A6) -> 45569 | P6: =IF(O6>$Q$1,TRUE) -> TRUE
A7: ='All Players'!A5 -> Nightmare91 | B7: =COUNTIFS(GameStats!C:C,A7,GameStats!D:D,"1",GameStats!B:B,">="&$Q$1) -> 0 | C7: =COUNTIFS(GameStats!C:C,A7,GameStats!B:B,">="&$Q$1) -> 18 | D7: =B7/C7 -> 0 | E7: =SUMIFS(GameStats!D:D,GameStats!C:C,A7,GameStats!B:B,">="&$Q$1)/C7 -> 9.2222222 | F7: =H7/I7 -> 0.93698155 | G7: =COUNTIFS(GameStats!I:I,A7,GameStats!B:B,">="&$Q$1) -> 16 | H7: =SUMIFS(GameStats!F:F,GameStats!C:C,A7,GameStats!B:B,">="&$Q$1) -> 66417 | I7: =SUMIFS(GameStats!G:G,GameStats!C:C,A7,GameStats!B:B,">="&$Q$1) -> 70884 | J7: =H7/C7 -> 3689.8333 | K7: =I7/C7 -> 3938 | L7: =G7/C7 -> 0.88888889 | M7: =('Elo model'!$E$14*PlayerStats!D5) + ('Elo model'!$F$14*(1/PlayerStats!E5)) + ('Elo model'!$G$14*PlayerStats!F5) + ('Elo model'!$H$14*(PlayerStats!L5/4)) -> 0.46314265 | N7: =_xlfn.MINIFS(GameStats!B:B,GameStats!C:C,A7) -> 44967 | O7: =_xlfn.MAXIFS(GameStats!B:B,GameStats!C:C,A7) -> 45569 | P7: =IF(O7>$Q$1,TRUE) -> TRUE
A8: ='All Players'!A56 -> Taptheslap | B8: =COUNTIFS(GameStats!C:C,A8,GameStats!D:D,"1",GameStats!B:B,">="&$Q$1) -> 2 | C8: =COUNTIFS(GameStats!C:C,A8,GameStats!B:B,">="&$Q$1) -> 17 | D8: =B8/C8 -> 0.11764706 | E8: =SUMIFS(GameStats!D:D,GameStats!C:C,A8,GameStats!B:B,">="&$Q$1)/C8 -> 9.8235294 | F8: =H8/I8 -> 1.2136461 | G8: =COUNTIFS(GameStats!I:I,A8,GameStats!B:B,">="&$Q$1) -> 15 | H8: =SUMIFS(GameStats!F:F,GameStats!C:C,A8,GameStats!B:B,">="&$Q$1) -> 43099 | I8: =SUMIFS(GameStats!G:G,GameStats!C:C,A8,GameStats!B:B,">="&$Q$1) -> 35512 | J8: =H8/C8 -> 2535.2353 | K8: =I8/C8 -> 2088.9412 | L8: =G8/C8 -> 0.88235294 | M8: =('Elo model'!$E$14*PlayerStats!D56) + ('Elo model'!$F$14*(1/PlayerStats!E56)) + ('Elo model'!$G$14*PlayerStats!F56) + ('Elo model'!$H$14*(PlayerStats!L56/4)) -> 0.099507786 | N8: =_xlfn.MINIFS(GameStats!B:B,GameStats!C:C,A8) -> 44995 | O8: =_xlfn.MAXIFS(GameStats!B:B,GameStats!C:C,A8) -> 45562 | P8: =IF(O8>$Q$1,TRUE) -> TRUE
A9: ='All Players'!A27 -> easterbunny | B9: =COUNTIFS(GameStats!C:C,A9,GameStats!D:D,"1",GameStats!B:B,">="&$Q$1) -> 2 | C9: =COUNTIFS(GameStats!C:C,A9,GameStats!B:B,">="&$Q$1) -> 17 | D9: =B9/C9 -> 0.11764706 | E9: =SUMIFS(GameStats!D:D,GameStats!C:C,A9,GameStats!B:B,">="&$Q$1)/C9 -> 9.8235294 | F9: =H9/I9 -> 1.1480879 | G9: =COUNTIFS(GameStats!I:I,A9,GameStats!B:B,">="&$Q$1) -> 22 | H9: =SUMIFS(GameStats!F:F,GameStats!C:C,A9,GameStats!B:B,">="&$Q$1) -> 52959 | I9: =SUMIFS(GameStats!G:G,GameStats!C:C,A9,GameStats!B:B,">="&$Q$1) -> 46128 | J9: =H9/C9 -> 3115.2353 | K9: =I9/C9 -> 2713.4118 | L9: =G9/C9 -> 1.2941176 | M9: =('Elo model'!$E$14*PlayerStats!D27) + ('Elo model'!$F$14*(1/PlayerStats!E27)) + ('Elo model'!$G$14*PlayerStats!F27) + ('Elo model'!$H$14*(PlayerStats!L27/4)) -> 0.18038183 | N9: =_xlfn.MINIFS(GameStats!B:B,GameStats!C:C,A9) -> 44974 | O9: =_xlfn.MAXIFS(GameStats!B:B,GameStats!C:C,A9) -> 45569 | P9: =IF(O9>$Q$1,TRUE) -> TRUE
A10: ='All Players'!A26 -> Derreger420 | B10: =COUNTIFS(GameStats!C:C,A10,GameStats!D:D,"1",GameStats!B:B,">="&$Q$1) -> 0 | C10: =COUNTIFS(GameStats!C:C,A10,GameStats!B:B,">="&$Q$1) -> 17 | D10: =B10/C10 -> 0 | E10: =SUMIFS(GameStats!D:D,GameStats!C:C,A10,GameStats!B:B,">="&$Q$1)/C10 -> 11.294118 | F10: =H10/I10 -> 0.90188099 | G10: =COUNTIFS(GameStats!I:I,A10,GameStats!B:B,">="&$Q$1) -> 9 | H10: =SUMIFS(GameStats!F:F,GameStats!C:C,A10,GameStats!B:B,">="&$Q$1) -> 29919 | I10: =SUMIFS(GameStats!G:G,GameStats!C:C,A10,GameStats!B:B,">="&$Q$1) -> 33174 | J10: =H10/C10 -> 1759.9412 | K10: =I10/C10 -> 1951.4118 | L10: =G10/C10 -> 0.52941176 | M10: =('Elo model'!$E$14*PlayerStats!D26) + ('Elo model'!$F$14*(1/PlayerStats!E26)) + ('Elo model'!$G$14*PlayerStats!F26) + ('Elo model'!$H$14*(PlayerStats!L26/4)) -> 0.32638611 | N10: =_xlfn.MINIFS(GameStats!B:B,GameStats!C:C,A10) -> 44974 | O10: =_xlfn.MAXIFS(GameStats!B:B,GameStats!C:C,A10) -> 45569 | P10: =IF(O10>$Q$1,TRUE) -> TRUE
A11: ='All Players'!A12 -> Trusty | B11: =COUNTIFS(GameStats!C:C,A11,GameStats!D:D,"1",GameStats!B:B,">="&$Q$1) -> 0 | C11: =COUNTIFS(GameStats!C:C,A11,GameStats!B:B,">="&$Q$1) -> 15 | D11: =B11/C11 -> 0 | E11: =SUMIFS(GameStats!D:D,GameStats!C:C,A11,GameStats!B:B,">="&$Q$1)/C11 -> 10.266667 | F11: =H11/I11 -> 0.99312174 | G11: =COUNTIFS(GameStats!I:I,A11,GameStats!B:B,">="&$Q$1) -> 5 | H11: =SUMIFS(GameStats!F:F,GameStats!C:C,A11,GameStats!B:B,">="&$Q$1) -> 11984 | I11: =SUMIFS(GameStats!G:G,GameStats!C:C,A11,GameStats!B:B,">="&$Q$1) -> 12067 | J11: =H11/C11 -> 798.93333 | K11: =I11/C11 -> 804.46667 | L11: =G11/C11 -> 0.33333333 | M11: =('Elo model'!$E$14*PlayerStats!D12) + ('Elo model'!$F$14*(1/PlayerStats!E12)) + ('Elo model'!$G$14*PlayerStats!F12) + ('Elo model'!$H$14*(PlayerStats!L12/4)) -> 0.14810724 | N11: =_xlfn.MINIFS(GameStats!B:B,GameStats!C:C,A11) -> 44967 | O11: =_xlfn.MAXIFS(GameStats!B:B,GameStats!C:C,A11) -> 45569 | P11: =IF(O11>$Q$1,TRUE) -> TRUE
A12: ='All Players'!A115 -> Chaos | B12: =COUNTIFS(GameStats!C:C,A12,GameStats!D:D,"1",GameStats!B:B,">="&$Q$1) -> 0 | C12: =COUNTIFS(GameStats!C:C,A12,GameStats!B:B,">="&$Q$1) -> 14 | D12: =B12/C12 -> 0 | E12: =SUMIFS(GameStats!D:D,GameStats!C:C,A12,GameStats!B:B,">="&$Q$1)/C12 -> 11.642857 | F12: =H12/I12 -> 0.83232759 | G12: =COUNTIFS(GameStats!I:I,A12,GameStats!B:B,">="&$Q$1) -> 1 | H12: =SUMIFS(GameStats!F:F,GameStats!C:C,A12,GameStats!B:B,">="&$Q$1) -> 9655 | I12: =SUMIFS(GameStats!G:G,GameStats!C:C,A12,GameStats!B:B,">="&$Q$1) -> 11600 | J12: =H12/C12 -> 689.64286 | K12: =I12/C12 -> 828.57143 | L12: =G12/C12 -> 0.071428571 | M12: =('Elo model'!$E$14*PlayerStats!D115) + ('Elo model'!$F$14*(1/PlayerStats!E115)) + ('Elo model'!$G$14*(PlayerStats!F115/1.75)) + ('Elo model'!$H$14*(PlayerStats!L115/4)) -> 0.046831989 | N12: =_xlfn.MINIFS(GameStats!B:B,GameStats!C:C,A12) -> 45044 | O12: =_xlfn.MAXIFS(GameStats!B:B,GameStats!C:C,A12) -> 45555 | P12: =IF(O12>$Q$1,TRUE) -> TRUE
A13: ='All Players'!A37 -> MinaMoto | B13: =COUNTIFS(GameStats!C:C,A13,GameStats!D:D,"1",GameStats!B:B,">="&$Q$1) -> 2 | C13: =COUNTIFS(GameStats!C:C,A13,GameStats!B:B,">="&$Q$1) -> 13 | D13: =B13/C13 -> 0.15384615 | E13: =SUMIFS(GameStats!D:D,GameStats!C:C,A13,GameStats!B:B,">="&$Q$1)/C13 -> 5.6923077 | F13: =H13/I13 -> 1.1605747 | G13: =COUNTIFS(GameStats!I:I,A13,GameStats!B:B,">="&$Q$1) -> 17 | H13: =SUMIFS(GameStats!F:F,GameStats!C:C,A13,GameStats!B:B,">="&$Q$1) -> 39340 | I13: =SUMIFS(GameStats!G:G,GameStats!C:C,A13,GameStats!B:B,">="&$Q$1) -> 33897 | J13: =H13/C13 -> 3026.1538 | K13: =I13/C13 -> 2607.4615 | L13: =G13/C13 -> 1.3076923 | M13: =('Elo model'!$E$14*PlayerStats!D37) + ('Elo model'!$F$14*(1/PlayerStats!E37)) + ('Elo model'!$G$14*PlayerStats!F37) + ('Elo model'!$H$14*(PlayerStats!L37/4)) -> 0.27155208 | N13: =_xlfn.MINIFS(GameStats!B:B,GameStats!C:C,A13) -> 44988 | O13: =_xlfn.MAXIFS(GameStats!B:B,GameStats!C:C,A13) -> 45562 | P13: =IF(O13>$Q$1,TRUE) -> TRUE
A14: ='All Players'!A90 -> Smoko21 | B14: =COUNTIFS(GameStats!C:C,A14,GameStats!D:D,"1",GameStats!B:B,">="&$Q$1) -> 0 | C14: =COUNTIFS(GameStats!C:C,A14,GameStats!B:B,">="&$Q$1) -> 13 | D14: =B14/C14 -> 0 | E14: =SUMIFS(GameStats!D:D,GameStats!C:C,A14,GameStats!B:B,">="&$Q$1)/C14 -> 7.9230769 | F14: =H14/I14 -> 0.93277544 | G14: =COUNTIFS(GameStats!I:I,A14,GameStats!B:B,">="&$Q$1) -> 7 | H14: =SUMIFS(GameStats!F:F,GameStats!C:C,A14,GameStats!B:B,">="&$Q$1) -> 43694 | I14: =SUMIFS(GameStats!G:G,GameStats!C:C,A14,GameStats!B:B,">="&$Q$1) -> 46843 | J14: =H14/C14 -> 3361.0769 | K14: =I14/C14 -> 3603.3077 | L14: =G14/C14 -> 0.53846154 | M14: =('Elo model'!$E$14*PlayerStats!D90) + ('Elo model'!$F$14*(1/PlayerStats!E90)) + ('Elo model'!$G$14*(PlayerStats!F90/1.75)) + ('Elo model'!$H$14*(PlayerStats!L90/4)) -> 0.088790705 | N14: =_xlfn.MINIFS(GameStats!B:B,GameStats!C:C,A14) -> 45023 | O14: =_xlfn.MAXIFS(GameStats!B:B,GameStats!C:C,A14) -> 45520 | P14: =IF(O14>$Q$1,TRUE) -> TRUE
A15: ='All Players'!A143 -> bambucha21 | B15: =COUNTIFS(GameStats!C:C,A15,GameStats!D:D,"1",GameStats!B:B,">="&$Q$1) -> 1 | C15: =COUNTIFS(GameStats!C:C,A15,GameStats!B:B,">="&$Q$1) -> 13 | D15: =B15/C15 -> 0.076923077 | E15: =SUMIFS(GameStats!D:D,GameStats!C:C,A15,GameStats!B:B,">="&$Q$1)/C15 -> 12.538462 | F15: =H15/I15 -> 0.91576584 | G15: =COUNTIFS(GameStats!I:I,A15,GameStats!B:B,">="&$Q$1) -> 18 | H15: =SUMIFS(GameStats!F:F,GameStats!C:C,A15,GameStats!B:B,">="&$Q$1) -> 26516 | I15: =SUMIFS(GameStats!G:G,GameStats!C:C,A15,GameStats!B:B,">="&$Q$1) -> 28955 | J15: =H15/C15 -> 2039.6923 | K15: =I15/C15 -> 2227.3077 | L15: =G15/C15 -> 1.3846154 | M15: =('Elo model'!$E$14*PlayerStats!D143) + ('Elo model'!$F$14*(1/PlayerStats!E143)) + ('Elo model'!$G$14*(PlayerStats!F143/1.75)) + ('Elo model'!$H$14*(PlayerStats!L143/4)) -> 0.11508189 | N15: =_xlfn.MINIFS(GameStats!B:B,GameStats!C:C,A15) -> 45380 | O15: =_xlfn.MAXIFS(GameStats!B:B,GameStats!C:C,A15) -> 45506 | P15: =IF(O15>$Q$1,TRUE) -> TRUE
A16: ='All Players'!A140 -> mappy | B16: =COUNTIFS(GameStats!C:C,A16,GameStats!D:D,"1",GameStats!B:B,">="&$Q$1) -> 0 | C16: =COUNTIFS(GameStats!C:C,A16,GameStats!B:B,">="&$Q$1) -> 12 | D16: =B16/C16 -> 0 | E16: =SUMIFS(GameStats!D:D,GameStats!C:C,A16,GameStats!B:B,">="&$Q$1)/C16 -> 7.5833333 | F16: =H16/I16 -> 0.90792018 | G16: =COUNTIFS(GameStats!I:I,A16,GameStats!B:B,">="&$Q$1) -> 30 | H16: =SUMIFS(GameStats!F:F,GameStats!C:C,A16,GameStats!B:B,">="&$Q$1) -> 46954 | I16: =SUMIFS(GameStats!G:G,GameStats!C:C,A16,GameStats!B:B,">="&$Q$1) -> 51716 | J16: =H16/C16 -> 3912.8333 | K16: =I16/C16 -> 4309.6667 | L16: =G16/C16 -> 2.5 | M16: =('Elo model'!$E$14*PlayerStats!D140) + ('Elo model'!$F$14*(1/PlayerStats!E140)) + ('Elo model'!$G$14*(PlayerStats!F140/1.75)) + ('Elo model'!$H$14*(PlayerStats!L140/4)) -> 0.13163223 | N16: =_xlfn.MINIFS(GameStats!B:B,GameStats!C:C,A16) -> 45380 | O16: =_xlfn.MAXIFS(GameStats!B:B,GameStats!C:C,A16) -> 45569 | P16: =IF(O16>$Q$1,TRUE) -> TRUE
A17: ='All Players'!A39 -> Darkknight | B17: =COUNTIFS(GameStats!C:C,A17,GameStats!D:D,"1",GameStats!B:B,">="&$Q$1) -> 0 | C17: =COUNTIFS(GameStats!C:C,A17,GameStats!B:B,">="&$Q$1) -> 12 | D17: =B17/C17 -> 0 | E17: =SUMIFS(GameStats!D:D,GameStats!C:C,A17,GameStats!B:B,">="&$Q$1)/C17 -> 10.5 | F17: =H17/I17 -> 1.0208958 | G17: =COUNTIFS(GameStats!I:I,A17,GameStats!B:B,">="&$Q$1) -> 4 | H17: =SUMIFS(GameStats!F:F,GameStats!C:C,A17,GameStats!B:B,">="&$Q$1) -> 11237 | I17: =SUMIFS(GameStats!G:G,GameStats!C:C,A17,GameStats!B:B,">="&$Q$1) -> 11007 | J17: =H17/C17 -> 936.41667 | K17: =I17/C17 -> 917.25 | L17: =G17/C17 -> 0.33333333 | M17: =('Elo model'!$E$14*PlayerStats!D39) + ('Elo model'!$F$14*(1/PlayerStats!E39)) + ('Elo model'!$G$14*PlayerStats!F39) + ('Elo model'!$H$14*(PlayerStats!L39/4)) -> 0.15341892 | N17: =_xlfn.MINIFS(GameStats!B:B,GameStats!C:C,A17) -> 44988 | O17: =_xlfn.MAXIFS(GameStats!B:B,GameStats!C:C,A17) -> 45555 | P17: =IF(O17>$Q$1,TRUE) -> TRUE
A18: ='All Players'!A122 -> tdawg | B18: =COUNTIFS(GameStats!C:C,A18,GameStats!D:D,"1",GameStats!B:B,">="&$Q$1) -> 1 | C18: =COUNTIFS(GameStats!C:C,A18,GameStats!B:B,">="&$Q$1) -> 11 | D18: =B18/C18 -> 0.090909091 | E18: =SUMIFS(GameStats!D:D,GameStats!C:C,A18,GameStats!B:B,">="&$Q$1)/C18 -> 6.8181818 | F18: =H18/I18 -> 1.143006 | G18: =COUNTIFS(GameStats!I:I,A18,GameStats!B:B,">="&$Q$1) -> 12 | H18: =SUMIFS(GameStats!F:F,GameStats!C:C,A18,GameStats!B:B,">="&$Q$1) -> 64733 | I18: =SUMIFS(GameStats!G:G,GameStats!C:C,A18,GameStats!B:B,">="&$Q$1) -> 56634 | J18: =H18/C18 -> 5884.8182 | K18: =I18/C18 -> 5148.5455 | L18: =G18/C18 -> 1.0909091 | M18: =('Elo model'!$E$14*PlayerStats!D122) + ('Elo model'!$F$14*(1/PlayerStats!E122)) + ('Elo model'!$G$14*(PlayerStats!F122/1.75)) + ('Elo model'!$H$14*(PlayerStats!L122/4)) -> 0.16719651 | N18: =_xlfn.MINIFS(GameStats!B:B,GameStats!C:C,A18) -> 45366 | O18: =_xlfn.MAXIFS(GameStats!B:B,GameStats!C:C,A18) -> 45569 | P18: =IF(O18>$Q$1,TRUE) -> TRUE
A19: ='All Players'!A19 -> StarDrifter | B19: =COUNTIFS(GameStats!C:C,A19,GameStats!D:D,"1",GameStats!B:B,">="&$Q$1) -> 1 | C19: =COUNTIFS(GameStats!C:C,A19,GameStats!B:B,">="&$Q$1) -> 11 | D19: =B19/C19 -> 0.090909091 | E19: =SUMIFS(GameStats!D:D,GameStats!C:C,A19,GameStats!B:B,">="&$Q$1)/C19 -> 11.909091 | F19: =H19/I19 -> 0.95564329 | G19: =COUNTIFS(GameStats!I:I,A19,GameStats!B:B,">="&$Q$1) -> 2 | H19: =SUMIFS(GameStats!F:F,GameStats!C:C,A19,GameStats!B:B,">="&$Q$1) -> 8230 | I19: =SUMIFS(GameStats!G:G,GameStats!C:C,A19,GameStats!B:B,">="&$Q$1) -> 8612 | J19: =H19/C19 -> 748.18182 | K19: =I19/C19 -> 782.90909 | L19: =G19/C19 -> 0.18181818 | M19: =('Elo model'!$E$14*PlayerStats!D19) + ('Elo model'!$F$14*(1/PlayerStats!E19)) + ('Elo model'!$G$14*(PlayerStats!F19/1.75)) + ('Elo model'!$H$14*(PlayerStats!L19/4)) -> 0.15290465 | N19: =_xlfn.MINIFS(GameStats!B:B,GameStats!C:C,A19) -> 44967 | O19: =_xlfn.MAXIFS(GameStats!B:B,GameStats!C:C,A19) -> 45555 | P19: =IF(O19>$Q$1,TRUE) -> TRUE
A20: ='All Players'!A229 -> NeoC0mplex | B20: =COUNTIFS(GameStats!C:C,A20,GameStats!D:D,"1",GameStats!B:B,">="&$Q$1) -> 0 | C20: =COUNTIFS(GameStats!C:C,A20,GameStats!B:B,">="&$Q$1) -> 11 | D20: =B20/C20 -> 0 | E20: =SUMIFS(GameStats!D:D,GameStats!C:C,A20,GameStats!B:B,">="&$Q$1)/C20 -> 12.818182 | F20: =H20/I20 -> 0.89210098 | G20: =COUNTIFS(GameStats!I:I,A20,GameStats!B:B,">="&$Q$1) -> 9 | H20: =SUMIFS(GameStats!F:F,GameStats!C:C,A20,GameStats!B:B,">="&$Q$1) -> 8764 | I20: =SUMIFS(GameStats!G:G,GameStats!C:C,A20,GameStats!B:B,">="&$Q$1) -> 9824 | J20: =H20/C20 -> 796.72727 | K20: =I20/C20 -> 893.09091 | L20: =G20/C20 -> 0.81818182 | M20: =('Elo model'!$E$14*PlayerStats!D229) + ('Elo model'!$F$14*(1/PlayerStats!E229)) + ('Elo model'!$G$14*(PlayerStats!F229/1.75)) + ('Elo model'!$H$14*(PlayerStats!L229/4)) -> 0.1231203 | N20: =_xlfn.MINIFS(GameStats!B:B,GameStats!C:C,A20) -> 45464 | O20: =_xlfn.MAXIFS(GameStats!B:B,GameStats!C:C,A20) -> 45562 | P20: =IF(O20>$Q$1,TRUE) -> TRUE
A21: ='All Players'!A61 -> noswear | B21: =COUNTIFS(GameStats!C:C,A21,GameStats!D:D,"1",GameStats!B:B,">="&$Q$1) -> 0 | C21: =COUNTIFS(GameStats!C:C,A21,GameStats!B:B,">="&$Q$1) -> 11 | D21: =B21/C21 -> 0 | E21: =SUMIFS(GameStats!D:D,GameStats!C:C,A21,GameStats!B:B,">="&$Q$1)/C21 -> 15.818182 | F21: =H21/I21 -> 0.86767266 | G21: =COUNTIFS(GameStats!I:I,A21,GameStats!B:B,">="&$Q$1) -> 4 | H21: =SUMIFS(GameStats!F:F,GameStats!C:C,A21,GameStats!B:B,">="&$Q$1) -> 7475 | I21: =SUMIFS(GameStats!G:G,GameStats!C:C,A21,GameStats!B:B,">="&$Q$1) -> 8615 | J21: =H21/C21 -> 679.54545 | K21: =I21/C21 -> 783.18182 | L21: =G21/C21 -> 0.36363636 | M21: =('Elo model'!$E$14*PlayerStats!D61) + ('Elo model'!$F$14*(1/PlayerStats!E61)) + ('Elo model'!$G$14*(PlayerStats!F61/1.75)) + ('Elo model'!$H$14*(PlayerStats!L61/4)) -> 0.13607823 | N21: =_xlfn.MINIFS(GameStats!B:B,GameStats!C:C,A21) -> 45002 | O21: =_xlfn.MAXIFS(GameStats!B:B,GameStats!C:C,A21) -> 45569 | P21: =IF(O21>$Q$1,TRUE) -> TRUE
A22: ='All Players'!A121 -> none | B22: =COUNTIFS(GameStats!C:C,A22,GameStats!D:D,"1",GameStats!B:B,">="&$Q$1) -> 1 | C22: =COUNTIFS(GameStats!C:C,A22,GameStats!B:B,">="&$Q$1) -> 10 | D22: =B22/C22 -> 0.1 | E22: =SUMIFS(GameStats!D:D,GameStats!C:C,A22,GameStats!B:B,">="&$Q$1)/C22 -> 5.9 | F22: =H22/I22 -> 1.1533057 | G22: =COUNTIFS(GameStats!I:I,A22,GameStats!B:B,">="&$Q$1) -> 20 | H22: =SUMIFS(GameStats!F:F,GameStats!C:C,A22,GameStats!B:B,">="&$Q$1) -> 48425 | I22: =SUMIFS(GameStats!G:G,GameStats!C:C,A22,GameStats!B:B,">="&$Q$1) -> 41988 | J22: =H22/C22 -> 4842.5 | K22: =I22/C22 -> 4198.8 | L22: =G22/C22 -> 2 | M22: =('Elo model'!$E$14*PlayerStats!D121) + ('Elo model'!$F$14*(1/PlayerStats!E121)) + ('Elo model'!$G$14*(PlayerStats!F121/1.75)) + ('Elo model'!$H$14*(PlayerStats!L121/4)) -> 0.15921578 | N22: =_xlfn.MINIFS(GameStats!B:B,GameStats!C:C,A22) -> 45366 | O22: =_xlfn.MAXIFS(GameStats!B:B,GameStats!C:C,A22) -> 45569 | P22: =IF(O22>$Q$1,TRUE) -> TRUE
A23: ='All Players'!A7 -> ColdMist | B23: =COUNTIFS(GameStats!C:C,A23,GameStats!D:D,"1",GameStats!B:B,">="&$Q$1) -> 1 | C23: =COUNTIFS(GameStats!C:C,A23,GameStats!B:B,">="&$Q$1) -> 10 | D23: =B23/C23 -> 0.1 | E23: =SUMIFS(GameStats!D:D,GameStats!C:C,A23,GameStats!B:B,">="&$Q$1)/C23 -> 7.7 | F23: =H23/I23 -> 1.2242844 | G23: =COUNTIFS(GameStats!I:I,A23,GameStats!B:B,">="&$Q$1) -> 15 | H23: =SUMIFS(GameStats!F:F,GameStats!C:C,A23,GameStats!B:B,">="&$Q$1) -> 55345 | I23: =SUMIFS(GameStats!G:G,GameStats!C:C,A23,GameStats!B:B,">="&$Q$1) -> 45206 | J23: =H23/C23 -> 5534.5 | K23: =I23/C23 -> 4520.6 | L23: =G23/C23 -> 1.5 | M23: =('Elo model'!$E$14*PlayerStats!D7) + ('Elo model'!$F$14*(1/PlayerStats!E7)) + ('Elo model'!$G$14*PlayerStats!F7) + ('Elo model'!$H$14*(PlayerStats!L7/4)) -> 0.18987789 | N23: =_xlfn.MINIFS(GameStats!B:B,GameStats!C:C,A23) -> 44967 | O23: =_xlfn.MAXIFS(GameStats!B:B,GameStats!C:C,A23) -> 45541 | P23: =IF(O23>$Q$1,TRUE) -> TRUE
A24: ='All Players'!A35 -> Dauda | B24: =COUNTIFS(GameStats!C:C,A24,GameStats!D:D,"1",GameStats!B:B,">="&$Q$1) -> 3 | C24: =COUNTIFS(GameStats!C:C,A24,GameStats!B:B,">="&$Q$1) -> 10 | D24: =B24/C24 -> 0.3 | E24: =SUMIFS(GameStats!D:D,GameStats!C:C,A24,GameStats!B:B,">="&$Q$1)/C24 -> 8.1 | F24: =H24/I24 -> 1.0542448 | G24: =COUNTIFS(GameStats!I:I,A24,GameStats!B:B,">="&$Q$1) -> 5 | H24: =SUMIFS(GameStats!F:F,GameStats!C:C,A24,GameStats!B:B,">="&$Q$1) -> 20018 | I24: =SUMIFS(GameStats!G:G,GameStats!C:C,A24,GameStats!B:B,">="&$Q$1) -> 18988 | J24: =H24/C24 -> 2001.8 | K24: =I24/C24 -> 1898.8 | L24: =G24/C24 -> 0.5 | M24: =('Elo model'!$E$14*PlayerStats!D35) + ('Elo model'!$F$14*(1/PlayerStats!E35)) + ('Elo model'!$G$14*(PlayerStats!F35/1.75)) + ('Elo model'!$H$14*(PlayerStats!L35/4)) -> 0.083302747 | N24: =_xlfn.MINIFS(GameStats!B:B,GameStats!C:C,A24) -> 44981 | O24: =_xlfn.MAXIFS(GameStats!B:B,GameStats!C:C,A24) -> 45562 | P24: =IF(O24>$Q$1,TRUE) -> TRUE
A25: ='All Players'!A10 -> Nerla | B25: =COUNTIFS(GameStats!C:C,A25,GameStats!D:D,"1",GameStats!B:B,">="&$Q$1) -> 0 | C25: =COUNTIFS(GameStats!C:C,A25,GameStats!B:B,">="&$Q$1) -> 10 | D25: =B25/C25 -> 0 | E25: =SUMIFS(GameStats!D:D,GameStats!C:C,A25,GameStats!B:B,">="&$Q$1)/C25 -> 8.2 | F25: =H25/I25 -> 1.0421369 | G25: =COUNTIFS(GameStats!I:I,A25,GameStats!B:B,">="&$Q$1) -> 2 | H25: =SUMIFS(GameStats!F:F,GameStats!C:C,A25,GameStats!B:B,">="&$Q$1) -> 15606 | I25: =SUMIFS(GameStats!G:G,GameStats!C:C,A25,GameStats!B:B,">="&$Q$1) -> 14975 | J25: =H25/C25 -> 1560.6 | K25: =I25/C25 -> 1497.5 | L25: =G25/C25 -> 0.2 | M25: =('Elo model'!$E$14*PlayerStats!D10) + ('Elo model'!$F$14*(1/PlayerStats!E10)) + ('Elo model'!$G$14*PlayerStats!F10) + ('Elo model'!$H$14*(PlayerStats!L10/4)) -> 0.17065286 | N25: =_xlfn.MINIFS(GameStats!B:B,GameStats!C:C,A25) -> 44967 | O25: =_xlfn.MAXIFS(GameStats!B:B,GameStats!C:C,A25) -> 45513 | P25: =IF(O25>$Q$1,TRUE) -> TRUE
A26: ='All Players'!A53 -> idorobots | B26: =COUNTIFS(GameStats!C:C,A26,GameStats!D:D,"1",GameStats!B:B,">="&$Q$1) -> 2 | C26: =COUNTIFS(GameStats!C:C,A26,GameStats!B:B,">="&$Q$1) -> 10 | D26: =B26/C26 -> 0.2 | E26: =SUMIFS(GameStats!D:D,GameStats!C:C,A26,GameStats!B:B,">="&$Q$1)/C26 -> 9 | F26: =H26/I26 -> 1.1407222 | G26: =COUNTIFS(GameStats!I:I,A26,GameStats!B:B,">="&$Q$1) -> 11 | H26: =SUMIFS(GameStats!F:F,GameStats!C:C,A26,GameStats!B:B,">="&$Q$1) -> 29693 | I26: =SUMIFS(GameStats!G:G,GameStats!C:C,A26,GameStats!B:B,">="&$Q$1) -> 26030 | J26: =H26/C26 -> 2969.3 | K26: =I26/C26 -> 2603 | L26: =G26/C26 -> 1.1 | M26: =('Elo model'!$E$14*PlayerStats!D53) + ('Elo model'!$F$14*(1/PlayerStats!E53)) + ('Elo model'!$G$14*(PlayerStats!F53/1.75)) + ('Elo model'!$H$14*(PlayerStats!L53/4)) -> 0.13995479 | N26: =_xlfn.MINIFS(GameStats!B:B,GameStats!C:C,A26) -> 44995 | O26: =_xlfn.MAXIFS(GameStats!B:B,GameStats!C:C,A26) -> 45499 | P26: =IF(O26>$Q$1,TRUE) -> TRUE
A27: ='All Players'!A9 -> Jax | B27: =COUNTIFS(GameStats!C:C,A27,GameStats!D:D,"1",GameStats!B:B,">="&$Q$1) -> 0 | C27: =COUNTIFS(GameStats!C:C,A27,GameStats!B:B,">="&$Q$1) -> 10 | D27: =B27/C27 -> 0 | E27: =SUMIFS(GameStats!D:D,GameStats!C:C,A27,GameStats!B:B,">="&$Q$1)/C27 -> 9.8 | F27: =H27/I27 -> 1.0158109 | G27: =COUNTIFS(GameStats!I:I,A27,GameStats!B:B,">="&$Q$1) -> 1 | H27: =SUMIFS(GameStats!F:F,GameStats!C:C,A27,GameStats!B:B,">="&$Q$1) -> 7003 | I27: =SUMIFS(GameStats!G:G,GameStats!C:C,A27,GameStats!B:B,">="&$Q$1) -> 6894 | J27: =H27/C27 -> 700.3 | K27: =I27/C27 -> 689.4 | L27: =G27/C27 -> 0.1 | M27: =('Elo model'!$E$14*PlayerStats!D9) + ('Elo model'!$F$14*(1/PlayerStats!E9)) + ('Elo model'!$G$14*PlayerStats!F9) + ('Elo model'!$H$14*(PlayerStats!L9/4)) -> 0.28883876 | N27: =_xlfn.MINIFS(GameStats!B:B,GameStats!C:C,A27) -> 44967 | O27: =_xlfn.MAXIFS(GameStats!B:B,GameStats!C:C,A27) -> 45436 | P27: =IF(O27>$Q$1,TRUE) -> TRUE
A28: ='All Players'!A66 -> SMW | B28: =COUNTIFS(GameStats!C:C,A28,GameStats!D:D,"1",GameStats!B:B,">="&$Q$1) -> 2 | C28: =COUNTIFS(GameStats!C:C,A28,GameStats!B:B,">="&$Q$1) -> 9 | D28: =B28/C28 -> 0.22222222 | E28: =SUMIFS(GameStats!D:D,GameStats!C:C,A28,GameStats!B:B,">="&$Q$1)/C28 -> 8.5555556 | F28: =H28/I28 -> 1.0576866 | G28: =COUNTIFS(GameStats!I:I,A28,GameStats!B:B,">="&$Q$1) -> 19 | H28: =SUMIFS(GameStats!F:F,GameStats!C:C,A28,GameStats!B:B,">="&$Q$1) -> 46076 | I28: =SUMIFS(GameStats!G:G,GameStats!C:C,A28,GameStats!B:B,">="&$Q$1) -> 43563 | J28: =H28/C28 -> 5119.5556 | K28: =I28/C28 -> 4840.3333 | L28: =G28/C28 -> 2.1111111 | M28: =('Elo model'!$E$14*PlayerStats!D66) + ('Elo model'!$F$14*(1/PlayerStats!E66)) + ('Elo model'!$G$14*(PlayerStats!F66/1.75)) + ('Elo model'!$H$14*(PlayerStats!L66/4)) -> 0.094230436 | N28: =_xlfn.MINIFS(GameStats!B:B,GameStats!C:C,A28) -> 45009 | O28: =_xlfn.MAXIFS(GameStats!B:B,GameStats!C:C,A28) -> 45562 | P28: =IF(O28>$Q$1,TRUE) -> TRUE
A29: ='All Players'!A40 -> GDArchangel | B29: =COUNTIFS(GameStats!C:C,A29,GameStats!D:D,"1",GameStats!B:B,">="&$Q$1) -> 0 | C29: =COUNTIFS(GameStats!C:C,A29,GameStats!B:B,">="&$Q$1) -> 9 | D29: =B29/C29 -> 0 | E29: =SUMIFS(GameStats!D:D,GameStats!C:C,A29,GameStats!B:B,">="&$Q$1)/C29 -> 13.444444 | F29: =H29/I29 -> 0.81208609 | G29: =COUNTIFS(GameStats!I:I,A29,GameStats!B:B,">="&$Q$1) -> 1 | H29: =SUMIFS(GameStats!F:F,GameStats!C:C,A29,GameStats!B:B,">="&$Q$1) -> 6867 | I29: =SUMIFS(GameStats!G:G,GameStats!C:C,A29,GameStats!B:B,">="&$Q$1) -> 8456 | J29: =H29/C29 -> 763 | K29: =I29/C29 -> 939.55556 | L29: =G29/C29 -> 0.11111111 | M29: =('Elo model'!$E$14*PlayerStats!D40) + ('Elo model'!$F$14*(1/PlayerStats!E40)) + ('Elo model'!$G$14*PlayerStats!F40) + ('Elo model'!$H$14*(PlayerStats!L40/4)) -> 0.16773541 | N29: =_xlfn.MINIFS(GameStats!B:B,GameStats!C:C,A29) -> 44988 | O29: =_xlfn.MAXIFS(GameStats!B:B,GameStats!C:C,A29) -> 45471 | P29: =IF(O29>$Q$1,TRUE) -> TRUE
A30: ='All Players'!A251 -> Apodyopsis | B30: =COUNTIFS(GameStats!C:C,A30,GameStats!D:D,"1",GameStats!B:B,">="&$Q$1) -> 0 | C30: =COUNTIFS(GameStats!C:C,A30,GameStats!B:B,">="&$Q$1) -> 9 | D30: =B30/C30 -> 0 | E30: =SUMIFS(GameStats!D:D,GameStats!C:C,A30,GameStats!B:B,">="&$Q$1)/C30 -> 14.888889 | F30: =H30/I30 -> 0.73958981 | G30: =COUNTIFS(GameStats!I:I,A30,GameStats!B:B,">="&$Q$1) -> 3 | H30: =SUMIFS(GameStats!F:F,GameStats!C:C,A30,GameStats!B:B,">="&$Q$1) -> 2380 | I30: =SUMIFS(GameStats!G:G,GameStats!C:C,A30,GameStats!B:B,">="&$Q$1) -> 3218 | J30: =H30/C30 -> 264.44444 | K30: =I30/C30 -> 357.55556 | L30: =G30/C30 -> 0.33333333 | M30: =('Elo model'!$E$14*PlayerStats!D251) + ('Elo model'!$F$14*(1/PlayerStats!E251)) + ('Elo model'!$G$14*(PlayerStats!F251/1.75)) + ('Elo model'!$H$14*(PlayerStats!L251/4)) -> 0.051904762 | N30: =_xlfn.MINIFS(GameStats!B:B,GameStats!C:C,A30) -> 45499 | O30: =_xlfn.MAXIFS(GameStats!B:B,GameStats!C:C,A30) -> 45569 | P30: =IF(O30>$Q$1,TRUE) -> TRUE
A31: ='All Players'!A100 -> DeKaL | B31: =COUNTIFS(GameStats!C:C,A31,GameStats!D:D,"1",GameStats!B:B,">="&$Q$1) -> 0 | C31: =COUNTIFS(GameStats!C:C,A31,GameStats!B:B,">="&$Q$1) -> 8 | D31: =B31/C31 -> 0 | E31: =SUMIFS(GameStats!D:D,GameStats!C:C,A31,GameStats!B:B,">="&$Q$1)/C31 -> 10 | F31: =H31/I31 -> 0.92605156 | G31: =COUNTIFS(GameStats!I:I,A31,GameStats!B:B,">="&$Q$1) -> 12 | H31: =SUMIFS(GameStats!F:F,GameStats!C:C,A31,GameStats!B:B,">="&$Q$1) -> 17745 | I31: =SUMIFS(GameStats!G:G,GameStats!C:C,A31,GameStats!B:B,">="&$Q$1) -> 19162 | J31: =H31/C31 -> 2218.125 | K31: =I31/C31 -> 2395.25 | L31: =G31/C31 -> 1.5 | M31: =('Elo model'!$E$14*PlayerStats!D100) + ('Elo model'!$F$14*(1/PlayerStats!E100)) + ('Elo model'!$G$14*(PlayerStats!F100/1.75)) + ('Elo model'!$H$14*(PlayerStats!L100/4)) -> 0.097600403 | N31: =_xlfn.MINIFS(GameStats!B:B,GameStats!C:C,A31) -> 45030 | O31: =_xlfn.MAXIFS(GameStats!B:B,GameStats!C:C,A31) -> 45569 | P31: =IF(O31>$Q$1,TRUE) -> TRUE
A32: ='All Players'!A154 -> irvipeaceful | B32: =COUNTIFS(GameStats!C:C,A32,GameStats!D:D,"1",GameStats!B:B,">="&$Q$1) -> 0 | C32: =COUNTIFS(GameStats!C:C,A32,GameStats!B:B,">="&$Q$1) -> 8 | D32: =B32/C32 -> 0 | E32: =SUMIFS(GameStats!D:D,GameStats!C:C,A32,GameStats!B:B,">="&$Q$1)/C32 -> 12.625 | F32: =H32/I32 -> 0.73756791 | G32: =COUNTIFS(GameStats!I:I,A32,GameStats!B:B,">="&$Q$1) -> 6 | H32: =SUMIFS(GameStats!F:F,GameStats!C:C,A32,GameStats!B:B,">="&$Q$1) -> 5295 | I32: =SUMIFS(GameStats!G:G,GameStats!C:C,A32,GameStats!B:B,">="&$Q$1) -> 7179 | J32: =H32/C32 -> 661.875 | K32: =I32/C32 -> 897.375 | L32: =G32/C32 -> 0.75 | M32: =('Elo model'!$E$14*PlayerStats!D154) + ('Elo model'!$F$14*(1/PlayerStats!E154)) + ('Elo model'!$G$14*(PlayerStats!F154/1.75)) + ('Elo model'!$H$14*(PlayerStats!L154/4)) -> 0.08859566 | N32: =_xlfn.MINIFS(GameStats!B:B,GameStats!C:C,A32) -> 45394 | O32: =_xlfn.MAXIFS(GameStats!B:B,GameStats!C:C,A32) -> 45569 | P32: =IF(O32>$Q$1,TRUE) -> TRUE
A33: ='All Players'!A129 -> untildeath | B33: =COUNTIFS(GameStats!C:C,A33,GameStats!D:D,"1",GameStats!B:B,">="&$Q$1) -> 0 | C33: =COUNTIFS(GameStats!C:C,A33,GameStats!B:B,">="&$Q$1) -> 7 | D33: =B33/C33 -> 0 | E33: =SUMIFS(GameStats!D:D,GameStats!C:C,A33,GameStats!B:B,">="&$Q$1)/C33 -> 12.857143 | F33: =H33/I33 -> 0.74129173 | G33: =COUNTIFS(GameStats!I:I,A33,GameStats!B:B,">="&$Q$1) -> 8 | H33: =SUMIFS(GameStats!F:F,GameStats!C:C,A33,GameStats!B:B,">="&$Q$1) -> 10215 | I33: =SUMIFS(GameStats!G:G,GameStats!C:C,A33,GameStats!B:B,">="&$Q$1) -> 13780 | J33: =H33/C33 -> 1459.2857 | K33: =I33/C33 -> 1968.5714 | L33: =G33/C33 -> 1.1428571 | M33: =('Elo model'!$E$14*PlayerStats!D129) + ('Elo model'!$F$14*(1/PlayerStats!E129)) + ('Elo model'!$G$14*(PlayerStats!F129/1.75)) + ('Elo model'!$H$14*(PlayerStats!L129/4)) -> 0.1357352 | N33: =_xlfn.MINIFS(GameStats!B:B,GameStats!C:C,A33) -> 45366 | O33: =_xlfn.MAXIFS(GameStats!B:B,GameStats!C:C,A33) -> 45541 | P33: =IF(O33>$Q$1,TRUE) -> TRUE
A34: ='All Players'!A138 -> heckman | B34: =COUNTIFS(GameStats!C:C,A34,GameStats!D:D,"1",GameStats!B:B,">="&$Q$1) -> 0 | C34: =COUNTIFS(GameStats!C:C,A34,GameStats!B:B,">="&$Q$1) -> 7 | D34: =B34/C34 -> 0 | E34: =SUMIFS(GameStats!D:D,GameStats!C:C,A34,GameStats!B:B,">="&$Q$1)/C34 -> 13.285714 | F34: =H34/I34 -> 0.89080367 | G34: =COUNTIFS(GameStats!I:I,A34,GameStats!B:B,">="&$Q$1) -> 2 | H34: =SUMIFS(GameStats!F:F,GameStats!C:C,A34,GameStats!B:B,">="&$Q$1) -> 5531 | I34: =SUMIFS(GameStats!G:G,GameStats!C:C,A34,GameStats!B:B,">="&$Q$1) -> 6209 | J34: =H34/C34 -> 790.14286 | K34: =I34/C34 -> 887 | L34: =G34/C34 -> 0.28571429 | M34: =('Elo model'!$E$14*PlayerStats!D138) + ('Elo model'!$F$14*(1/PlayerStats!E138)) + ('Elo model'!$G$14*(PlayerStats!F138/1.75)) + ('Elo model'!$H$14*(PlayerStats!L138/4)) -> 0.085392457 | N34: =_xlfn.MINIFS(GameStats!B:B,GameStats!C:C,A34) -> 45373 | O34: =_xlfn.MAXIFS(GameStats!B:B,GameStats!C:C,A34) -> 45443 | P34: =IF(O34>$Q$1,TRUE) -> TRUE
A35: ='All Players'!A84 -> tbatch1 | B35: =COUNTIFS(GameStats!C:C,A35,GameStats!D:D,"1",GameStats!B:B,">="&$Q$1) -> 0 | C35: =COUNTIFS(GameStats!C:C,A35,GameStats!B:B,">="&$Q$1) -> 7 | D35: =B35/C35 -> 0 | E35: =SUMIFS(GameStats!D:D,GameStats!C:C,A35,GameStats!B:B,">="&$Q$1)/C35 -> 15.142857 | F35: =H35/I35 -> 0.65425532 | G35: =COUNTIFS(GameStats!I:I,A35,GameStats!B:B,">="&$Q$1) -> 3 | H35: =SUMIFS(GameStats!F:F,GameStats!C:C,A35,GameStats!B:B,">="&$Q$1) -> 1968 | I35: =SUMIFS(GameStats!G:G,GameStats!C:C,A35,GameStats!B:B,">="&$Q$1) -> 3008 | J35: =H35/C35 -> 281.14286 | K35: =I35/C35 -> 429.71429 | L35: =G35/C35 -> 0.42857143 | M35: =('Elo model'!$E$14*PlayerStats!D84) + ('Elo model'!$F$14*(1/PlayerStats!E84)) + ('Elo model'!$G$14*(PlayerStats!F84/1.75)) + ('Elo model'!$H$14*(PlayerStats!L84/4)) -> 0.31186037 | N35: =_xlfn.MINIFS(GameStats!B:B,GameStats!C:C,A35) -> 45016 | O35: =_xlfn.MAXIFS(GameStats!B:B,GameStats!C:C,A35) -> 45548 | P35: =IF(O35>$Q$1,TRUE) -> TRUE
A36: ='All Players'!A204 -> Schneejager | B36: =COUNTIFS(GameStats!C:C,A36,GameStats!D:D,"1",GameStats!B:B,">="&$Q$1) -> 0 | C36: =COUNTIFS(GameStats!C:C,A36,GameStats!B:B,">="&$Q$1) -> 6 | D36: =B36/C36 -> 0 | E36: =SUMIFS(GameStats!D:D,GameStats!C:C,A36,GameStats!B:B,">="&$Q$1)/C36 -> 7.3333333 | F36: =H36/I36 -> 0.90980931 | G36: =COUNTIFS(GameStats!I:I,A36,GameStats!B:B,">="&$Q$1) -> 12 | H36: =SUMIFS(GameStats!F:F,GameStats!C:C,A36,GameStats!B:B,">="&$Q$1) -> 29819 | I36: =SUMIFS(GameStats!G:G,GameStats!C:C,A36,GameStats!B:B,">="&$Q$1) -> 32775 | J36: =H36/C36 -> 4969.8333 | K36: =I36/C36 -> 5462.5 | L36: =G36/C36 -> 2 | M36: =('Elo model'!$E$14*PlayerStats!D204) + ('Elo model'!$F$14*(1/PlayerStats!E204)) + ('Elo model'!$G$14*(PlayerStats!F204/1.75)) + ('Elo model'!$H$14*(PlayerStats!L204/4)) -> 0.053666921 | N36: =_xlfn.MINIFS(GameStats!B:B,GameStats!C:C,A36) -> 45443 | O36: =_xlfn.MAXIFS(GameStats!B:B,GameStats!C:C,A36) -> 45569 | P36: =IF(O36>$Q$1,TRUE) -> TRUE
A37: ='All Players'!A38 -> Jirenuber | B37: =COUNTIFS(GameStats!C:C,A37,GameStats!D:D,"1",GameStats!B:B,">="&$Q$1) -> 1 | C37: =COUNTIFS(GameStats!C:C,A37,GameStats!B:B,">="&$Q$1) -> 6 | D37: =B37/C37 -> 0.16666667 | E37: =SUMIFS(GameStats!D:D,GameStats!C:C,A37,GameStats!B:B,">="&$Q$1)/C37 -> 8 | F37: =H37/I37 -> 0.93534718 | G37: =COUNTIFS(GameStats!I:I,A37,GameStats!B:B,">="&$Q$1) -> 4 | H37: =SUMIFS(GameStats!F:F,GameStats!C:C,A37,GameStats!B:B,">="&$Q$1) -> 13686 | I37: =SUMIFS(GameStats!G:G,GameStats!C:C,A37,GameStats!B:B,">="&$Q$1) -> 14632 | J37: =H37/C37 -> 2281 | K37: =I37/C37 -> 2438.6667 | L37: =G37/C37 -> 0.66666667 | M37: =('Elo model'!$E$14*PlayerStats!D38) + ('Elo model'!$F$14*(1/PlayerStats!E38)) + ('Elo model'!$G$14*PlayerStats!F38) + ('Elo model'!$H$14*(PlayerStats!L38/4)) -> 0.15459851 | N37: =_xlfn.MINIFS(GameStats!B:B,GameStats!C:C,A37) -> 44988 | O37: =_xlfn.MAXIFS(GameStats!B:B,GameStats!C:C,A37) -> 45499 | P37: =IF(O37>$Q$1,TRUE) -> TRUE
A38: ='All Players'!A220 -> merton | B38: =COUNTIFS(GameStats!C:C,A38,GameStats!D:D,"1",GameStats!B:B,">="&$Q$1) -> 0 | C38: =COUNTIFS(GameStats!C:C,A38,GameStats!B:B,">="&$Q$1) -> 6 | D38: =B38/C38 -> 0 | E38: =SUMIFS(GameStats!D:D,GameStats!C:C,A38,GameStats!B:B,">="&$Q$1)/C38 -> 11.333333 | F38: =H38/I38 -> 0.82804233 | G38: =COUNTIFS(GameStats!I:I,A38,GameStats!B:B,">="&$Q$1) -> 2 | H38: =SUMIFS(GameStats!F:F,GameStats!C:C,A38,GameStats!B:B,">="&$Q$1) -> 1565 | I38: =SUMIFS(GameStats!G:G,GameStats!C:C,A38,GameStats!B:B,">="&$Q$1) -> 1890 | J38: =H38/C38 -> 260.83333 | K38: =I38/C38 -> 315 | L38: =G38/C38 -> 0.33333333 | M38: =('Elo model'!$E$14*PlayerStats!D220) + ('Elo model'!$F$14*(1/PlayerStats!E220)) + ('Elo model'!$G$14*(PlayerStats!F220/1.75)) + ('Elo model'!$H$14*(PlayerStats!L220/4)) -> 0.068116294 | N38: =_xlfn.MINIFS(GameStats!B:B,GameStats!C:C,A38) -> 45457 | O38: =_xlfn.MAXIFS(GameStats!B:B,GameStats!C:C,A38) -> 45541 | P38: =IF(O38>$Q$1,TRUE) -> TRUE
A39: ='All Players'!A184 -> Circa | B39: =COUNTIFS(GameStats!C:C,A39,GameStats!D:D,"1",GameStats!B:B,">="&$Q$1) -> 0 | C39: =COUNTIFS(GameStats!C:C,A39,GameStats!B:B,">="&$Q$1) -> 6 | D39: =B39/C39 -> 0 | E39: =SUMIFS(GameStats!D:D,GameStats!C:C,A39,GameStats!B:B,">="&$Q$1)/C39 -> 12.166667 | F39: =H39/I39 -> 0.77469541 | G39: =COUNTIFS(GameStats!I:I,A39,GameStats!B:B,">="&$Q$1) -> 4 | H39: =SUMIFS(GameStats!F:F,GameStats!C:C,A39,GameStats!B:B,">="&$Q$1) -> 8266 | I39: =SUMIFS(GameStats!G:G,GameStats!C:C,A39,GameStats!B:B,">="&$Q$1) -> 10670 | J39: =H39/C39 -> 1377.6667 | K39: =I39/C39 -> 1778.3333 | L39: =G39/C39 -> 0.66666667 | M39: =('Elo model'!$E$14*PlayerStats!D184) + ('Elo model'!$F$14*(1/PlayerStats!E184)) + ('Elo model'!$G$14*(PlayerStats!F184/1.75)) + ('Elo model'!$H$14*(PlayerStats!L184/4)) -> 0.064786967 | N39: =_xlfn.MINIFS(GameStats!B:B,GameStats!C:C,A39) -> 45422 | O39: =_xlfn.MAXIFS(GameStats!B:B,GameStats!C:C,A39) -> 45527 | P39: =IF(O39>$Q$1,TRUE) -> TRUE
A40: ='All Players'!A180 -> CREATION | B40: =COUNTIFS(GameStats!C:C,A40,GameStats!D:D,"1",GameStats!B:B,">="&$Q$1) -> 0 | C40: =COUNTIFS(GameStats!C:C,A40,GameStats!B:B,">="&$Q$1) -> 6 | D40: =B40/C40 -> 0 | E40: =SUMIFS(GameStats!D:D,GameStats!C:C,A40,GameStats!B:B,">="&$Q$1)/C40 -> 12.333333 | F40: =H40/I40 -> 0.95532314 | G40: =COUNTIFS(GameStats!I:I,A40,GameStats!B:B,">="&$Q$1) -> 1 | H40: =SUMIFS(GameStats!F:F,GameStats!C:C,A40,GameStats!B:B,">="&$Q$1) -> 15802 | I40: =SUMIFS(GameStats!G:G,GameStats!C:C,A40,GameStats!B:B,">="&$Q$1) -> 16541 | J40: =H40/C40 -> 2633.6667 | K40: =I40/C40 -> 2756.8333 | L40: =G40/C40 -> 0.16666667 | M40: =('Elo model'!$E$14*PlayerStats!D180) + ('Elo model'!$F$14*(1/PlayerStats!E180)) + ('Elo model'!$G$14*(PlayerStats!F180/1.75)) + ('Elo model'!$H$14*(PlayerStats!L180/4)) -> 0.053401361 | N40: =_xlfn.MINIFS(GameStats!B:B,GameStats!C:C,A40) -> 45415 | O40: =_xlfn.MAXIFS(GameStats!B:B,GameStats!C:C,A40) -> 45534 | P40: =IF(O40>$Q$1,TRUE) -> TRUE
...

Sheet Elo model
E8: Secret sauce ELO model
E10: (WinrateWeight * (WinrateCell)) + (AvgPlacementWeight * (1/AvgPlacementCell)) + (KDWeight * KDCell) + (AvgRivalsWeight * AvgRivalsCell)
E12: Weight
E13: Winrate | F13: AVG Placement | G13: KD | H13: AVG rivals
D14: Official | E14: 0.5 | F14: 0.25 | G14: 0.15 | H14: 0.1 | I14: =SUM(E14:H14) -> 1
D16: Alternate | I16: =H16+G16+F16+E16 -> 0
M23: Win % | N23: Placement | O23: Rival Elo | P23: KD
C24: KD | E24: AVG Rival | F24: AVG Mod | G24: Win Percentage | H24: Mod | I24: Placement | K24: number for weight | M24: Elo | N24: Elo output | P24: ELO
C25: 2 | D25: =C25/1.75 -> 1.1428571 | E25: 5 | F25: =E25/4 -> 1.25 | G25: 1 | H25: =G25-0.15 -> 0.85 | I25: 1 | K25: =1/I25 -> 1 | M25: =H25*'Elo model'!$E$14 -> 0.425 | N25: ='Elo model'!$F$14*K25 -> 0.25 | O25: =F25*0.1 -> 0.125 | P25: =D25*'Elo model'!$G$14 -> 0.17142857 | Q25: =SUM(M25:P25) -> 0.97142857 | V25: 200
C26: 1.95 | D26: =C26/1.75 -> 1.1142857 | E26: 4.9 | F26: =E26/4 -> 1.225 | G26: 0.98 | H26: =G26-0.15 -> 0.83 | I26: 2 | K26: =1/I26 -> 0.5 | M26: =H26*'Elo model'!$E$14 -> 0.415 | N26: ='Elo model'!$F$14*K26 -> 0.125 | O26: =F26*0.1 -> 0.1225 | P26: =D26*'Elo model'!$G$14 -> 0.16714286 | Q26: =SUM(M26:P26) -> 0.82964286 | V26: 95
C27: 1.9 | D27: =C27/1.75 -> 1.0857143 | E27: 4.8 | F27: =E27/4 -> 1.2 | G27: 0.97 | H27: =G27-0.15 -> 0.82 | I27: 3 | K27: =1/I27 -> 0.33333333 | M27: =H27*'Elo model'!$E$14 -> 0.41 | N27: ='Elo model'!$F$14*K27 -> 0.083333333 | O27: =F27*0.1 -> 0.12 | P27: =D27*'Elo model'!$G$14 -> 0.16285714 | Q27: =SUM(M27:P27) -> 0.77619048
C28: 1.8 | D28: =C28/1.75 -> 1.0285714 | E28: 4.75 | F28: =E28/4 -> 1.1875 | G28: 0.95 | H28: =G28-0.15 -> 0.8 | I28: 4 | K28: =1/I28 -> 0.25 | M28: =H28*'Elo model'!$E$14 -> 0.4 | N28: ='Elo model'!$F$14*K28 -> 0.0625 | O28: =F28*0.1 -> 0.11875 | P28: =D28*'Elo model'!$G$14 -> 0.15428571 | Q28: =SUM(M28:P28) -> 0.73553571 | U28: =1/22 -> 0.045454545
C29: 1.75 | D29: =C29/1.75 -> 1 | E29: 4.5 | F29: =E29/4 -> 1.125 | G29: 0.9 | H29: =G29-0.15 -> 0.75 | I29: 5 | K29: =1/I29 -> 0.2 | M29: =H29*'Elo model'!$E$14 -> 0.375 | N29: ='Elo model'!$F$14*K29 -> 0.05 | O29: =F29*0.1 -> 0.1125 | P29: =D29*'Elo model'!$G$14 -> 0.15 | Q29: =SUM(M29:P29) -> 0.6875
C30: 1.7 | D30: =C30/1.75 -> 0.97142857 | E30: 4.25 | F30: =E30/4 -> 1.0625 | G30: 0.85 | H30: =G30-0.15 -> 0.7 | I30: 6 | K30: =1/I30 -> 0.16666667 | M30: =H30*'Elo model'!$E$14 -> 0.35 | N30: ='Elo model'!$F$14*K30 -> 0.041666667 | O30: =F30*0.1 -> 0.10625 | P30: =D30*'Elo model'!$G$14 -> 0.14571429 | Q30: =SUM(M30:P30) -> 0.64363095
C31: 1.6 | D31: =C31/1.75 -> 0.91428571 | E31: 4 | F31: =E31/4 -> 1 | G31: 0.8 | H31: =G31-0.15 -> 0.65 | I31: 7 | K31: =1/I31 -> 0.14285714 | M31: =H31*'Elo model'!$E$14 -> 0.325 | N31: ='Elo model'!$F$14*K31 -> 0.035714286 | O31: =F31*0.1 -> 0.1 | P31: =D31*'Elo model'!$G$14 -> 0.13714286 | Q31: =SUM(M31:P31) -> 0.59785714
C32: 1.5 | D32: =C32/1.75 -> 0.85714286 | E32: 3.75 | F32: =E32/4 -> 0.9375 | G32: 0.75 | H32: =G32-0.15 -> 0.6 | I32: 8 | K32: =1/I32 -> 0.125 | M32: =H32*'Elo model'!$E$14 -> 0.3 | N32: ='Elo model'!$F$14*K32 -> 0.03125 | O32: =F32*0.1 -> 0.09375 | P32: =D32*'Elo model'!$G$14 -> 0.12857143 | Q32: =SUM(M32:P32) -> 0.55357143
C33: 1.4 | D33: =C33/1.75 -> 0.8 | E33: 3.5 | F33: =E33/4 -> 0.875 | G33: 0.7 | H33: =G33-0.15 -> 0.55 | I33: 9 | K33: =1/I33 -> 0.11111111 | M33: =H33*'Elo model'!$E$14 -> 0.275 | N33: ='Elo model'!$F$14*K33 -> 0.027777778 | O33: =F33*0.1 -> 0.0875 | P33: =D33*'Elo model'!$G$14 -> 0.12 | Q33: =SUM(M33:P33) -> 0.51027778
C34: 1.3 | D34: =C34/1.75 -> 0.74285714 | E34: 3.25 | F34: =E34/4 -> 0.8125 | G34: 0.65 | H34: =G34-0.15 -> 0.5 | I34: 10 | K34: =1/I34 -> 0.1 | M34: =H34*'Elo model'!$E$14 -> 0.25 | N34: ='Elo model'!$F$14*K34 -> 0.025 | O34: =F34*0.1 -> 0.08125 | P34: =D34*'Elo model'!$G$14 -> 0.11142857 | Q34: =SUM(M34:P34) -> 0.46767857
C35: 1.2 | D35: =C35/1.75 -> 0.68571429 | E35: 3 | F35: =E35/4 -> 0.75 | G35: 0.6 | H35: =G35-0.15 -> 0.45 | I35: 11 | K35: =1/I35 -> 0.090909091 | M35: =H35*'Elo model'!$E$14 -> 0.225 | N35: ='Elo model'!$F$14*K35 -> 0.022727273 | O35: =F35*0.1 -> 0.075 | P35: =D35*'Elo model'!$G$14 -> 0.10285714 | Q35: =SUM(M35:P35) -> 0.42558442
C36: 1.1 | D36: =C36/1.75 -> 0.62857143 | E36: 2.75 | F36: =E36/4 -> 0.6875 | G36: 0.55 | H36: =G36-0.15 -> 0.4 | I36: 12 | K36: =1/I36 -> 0.083333333 | M36: =H36*'Elo model'!$E$14 -> 0.2 | N36: ='Elo model'!$F$14*K36 -> 0.020833333 | O36: =F36*0.1 -> 0.06875 | P36: =D36*'Elo model'!$G$14 -> 0.094285714 | Q36: =SUM(M36:P36) -> 0.38386905
C37: 1 | D37: =C37/1.75 -> 0.57142857 | E37: 2.5 | F37: =E37/4 -> 0.625 | G37: 0.5 | H37: =G37-0.15 -> 0.35 | I37: 13 | K37: =1/I37 -> 0.076923077 | M37: =H37*'Elo model'!$E$14 -> 0.175 | N37: ='Elo model'!$F$14*K37 -> 0.019230769 | O37: =F37*0.1 -> 0.0625 | P37: =D37*'Elo model'!$G$14 -> 0.085714286 | Q37: =SUM(M37:P37) -> 0.34244505
C38: 0.9 | D38: =C38/1.75 -> 0.51428571 | E38: 2.25 | F38: =E38/4 -> 0.5625 | G38: 0.45 | H38: =G38-0.15 -> 0.3 | I38: 14 | K38: =1/I38 -> 0.071428571 | M38: =H38*'Elo model'!$E$14 -> 0.15 | N38: ='Elo model'!$F$14*K38 -> 0.017857143 | O38: =F38*0.1 -> 0.05625 | P38: =D38*'Elo model'!$G$14 -> 0.077142857 | Q38: =SUM(M38:P38) -> 0.30125
C39: 0.8 | D39: =C39/1.75 -> 0.45714286 | E39: 2 | F39: =E39/4 -> 0.5 | G39: 0.4 | H39: =G39-0.15 -> 0.25 | I39: 15 | K39: =1/I39 -> 0.066666667 | M39: =H39*'Elo model'!$E$14 -> 0.125 | N39: ='Elo model'!$F$14*K39 -> 0.016666667 | O39: =F39*0.1 -> 0.05 | P39: =D39*'Elo model'!$G$14 -> 0.068571429 | Q39: =SUM(M39:P39) -> 0.2602381
C40: 0.7 | D40: =C40/1.75 -> 0.4 | E40: 1.75 | F40: =E40/4 -> 0.4375 | G40: 0.35 | H40: =G40-0.15 -> 0.2 | I40: 16 | K40: =1/I40 -> 0.0625 | M40: =H40*'Elo model'!$E$14 -> 0.1 | N40: ='Elo model'!$F$14*K40 -> 0.015625 | O40: =F40*0.1 -> 0.04375 | P40: =D40*'Elo model'!$G$14 -> 0.06 | Q40: =SUM(M40:P40) -> 0.219375
... C42: 0.5 | D42: =C42/1.75 -> 0.28571429 | E42: 1.25 | F42: =E42/4 -> 0.3125 | G42: 0.25 | H42: =G42-0.15 -> 0.1 | I42: 18 | K42: =1/I42 -> 0.055555556 | M42: =H42*'Elo model'!$E$14 -> 0.05 | N42: ='Elo model'!$F$14*K42 -> 0.013888889 | O42: =F42*0.1 -> 0.03125 | P42: =D42*'Elo model'!$G$14 -> 0.042857143 | Q42: =SUM(M42:P42) -> 0.13799603
C43: 0.4 | D43: =C43/1.75 -> 0.22857143 | E43: 1 | F43: =E43/4 -> 0.25 | G43: 0.2 | H43: =G43-0.15 -> 0.05 | I43: 19 | K43: =1/I43 -> 0.052631579 | M43: =H43*'Elo model'!$E$14 -> 0.025 | N43: ='Elo model'!$F$14*K43 -> 0.013157895 | O43: =F43*0.1 -> 0.025 | P43: =D43*'Elo model'!$G$14 -> 0.034285714 | Q43: =SUM(M43:P43) -> 0.097443609 | W43: 0.04
C44: 0.3 | D44: =C44/1.75 -> 0.17142857 | E44: 0.75 | F44: =E44/4 -> 0.1875 | G44: 0.15 | H44: 0 | I44: 20 | K44: =1/I44 -> 0.05 | M44: =H44*'Elo model'!$E$14 -> 0 | N44: ='Elo model'!$F$14*K44 -> 0.0125 | O44: =F44*0.1 -> 0.01875 | P44: =D44*'Elo model'!$G$14 -> 0.025714286 | Q44: =SUM(M44:P44) -> 0.056964286
C45: 0.2 | D45: =C45/1.75 -> 0.11428571 | E45: 0.5 | F45: =E45/4 -> 0.125 | G45: 0.1 | H45: 0 | I45: 21 | K45: =1/I45 -> 0.047619048 | M45: =H45*'Elo model'!$E$14 -> 0 | N45: ='Elo model'!$F$14*K45 -> 0.011904762 | O45: =F45*0.1 -> 0.0125 | P45: =D45*'Elo model'!$G$14 -> 0.017142857 | Q45: =SUM(M45:P45) -> 0.041547619
C46: 0.1 | D46: =C46/1.75 -> 0.057142857 | E46: 0.25 | F46: =E46/4 -> 0.0625 | G46: 0.05 | H46: 0 | I46: 22 | K46: =1/I46 -> 0.045454545 | M46: =H46*'Elo model'!$E$14 -> 0 | N46: ='Elo model'!$F$14*K46 -> 0.011363636 | O46: =F46*0.1 -> 0.00625 | P46: =D46*'Elo model'!$G$14 -> 0.0085714286 | Q46: =SUM(M46:P46) -> 0.026185065
C47: 0 | D47: =C47/1.75 -> 0 | E47: 0 | F47: =E47/4 -> 0 | G47: 0 | H47: 0 | I47: 23 | K47: =1/I47 -> 0.043478261 | M47: =H47*'Elo model'!$E$14 -> 0 | N47: ='Elo model'!$F$14*K47 -> 0.010869565 | O47: =F47*0.1 -> 0 | P47: =D47*'Elo model'!$G$14 -> 0 | Q47: =SUM(M47:P47) -> 0.010869565
G53: Games Played | H53: Games Won | I53: Win rate | J53: Weight | K53: Elo
G54: 1 | H54: 1 | I54: 1 | J54: 0.125 | K54: =I54*J54 -> 0.125 | Q54: 0.25
